Workbook

Sheet Sheet1
A3: Nom du projet | B3: OrangeHRM - Phase 1 : Analyse et conception des tests (projet final ISTQB GoMyCode)
A4: Date de livraison | B4: 46316
A5: Date de conception des tests | B5: 2026-10-15
A6: Conçu par | B6: EL ABDELLAOUI JABER
A7: Développeur | B7: OrangeHRM Inc. - démo open source, https://opensource-demo.orangehrmlive.com/web/index.php/auth/login
A8: Navigateurs | B8: Google Chrome, dernière version stable (ordinateur)
A9: Version Android | B9: N/A
A10: Version iOS | B10: N/A
A11: Pays | B11: Maroc
A12: PC | B12: PC de bureau
A13: Environnement Linux | B13: NA
A14: Version Windows | B14: Windows 11

Sheet Sheet2
A1: compagne | B1: Suite | C1: ID test | D1: titre de test | E1: type de test | F1: précondition | G1: N° d'étape | H1: Etapes | I1: DONNées de test | J1: Résultat attendu | K1: résultat obtenu | L1: statut | M1: ID exigence | N1: ID scénario | O1: Objectif | P1: Priorité | Q1: Technique
A2: OrangeHRM Phase 1 | B2: TS-01 Authentification (Login / Logout) | C2: TC-001 | D2: Connexion avec des identifiants Admin valides | E2: fonctionnel | F2: Chrome (dernière version stable) ouvert sur la page de connexion de la démo ; aucun utilisateur connecté. | G2: 1 | H2: Saisir 'Admin' dans Username | I2: Username : Admin Password : admin123 | J2: 'Admin' s'affiche dans le champ Username | K2: Username 'Admin' s'affiche correctement | L2: Réussi | M2: REQ-001, REQ-004 | N2: SC-001 | O2: Vérifier qu'un utilisateur valide est authentifié et que le mot de passe est masqué (règle R1 de la table de décision). | P2: Haute | Q2: Test par tables de décision
G3: 2 | H3: Saisir 'admin123' dans Password | J3: Des caractères de masquage s'affichent ; le texte en clair 'admin123' n'est pas visible | K3: Le mot de passe est masqué (invisible) | L3: Réussi
G4: 3 | H4: Cliquer sur Login | J4: L'URL contient '/dashboard/index' ; le titre de page 'Dashboard' et le menu déroulant de l'utilisateur (en haut à droite) s'affichent | K4: Redirection vers le Dashboard | L4: Réussi
C5: TC-002 | D5: Connexion avec un nom d'utilisateur valide et un mot de passe erroné | E5: fonctionnel | F5: Chrome (dernière version stable) ouvert sur la page de connexion de la démo ; aucun utilisateur connecté. | G5: 1 | H5: Saisir 'Admin' dans Username | I5: Username : Admin Password : admin999 | J5: La valeur s'affiche | K5: Username 'Admin' s'affiche correctement | L5: Réussi | M5: REQ-002 | N5: SC-002 | O5: Vérifier qu'un mot de passe invalide est refusé (règle R2 de la table de décision). | P5: Haute | Q5: Test par tables de décision
G6: 2 | H6: Saisir 'admin999' dans Password | J6: La valeur est masquée | K6: Le mot de passe est masqué (invisible) | L6: Réussi
G7: 3 | H7: Cliquer sur Login | J7: L'alerte 'Invalid credentials' s'affiche ; l'URL contient toujours '/auth/login' ; le Dashboard ne s'affiche pas | K7: Le message « Invalid credentials » s'affiche et l'utilisateur reste sur la page de connexion | L7: Réussi
C8: TC-003 | D8: Connexion avec un nom d'utilisateur inconnu et un mot de passe valide | E8: fonctionnel | F8: Chrome (dernière version stable) ouvert sur la page de connexion de la démo ; aucun utilisateur connecté. | G8: 1 | H8: Saisir 'Lion13' dans Username | I8: Username : Lion13 Password : admin123 | J8: La valeur s'affiche | K8: Username 'Lion13' s'affiche correctement | L8: Réussi | M8: REQ-002 | N8: SC-002 | O8: Vérifier qu'un nom d'utilisateur inconnu est refusé (règle R3 de la table de décision). | P8: Haute | Q8: Test par tables de décision
G9: 2 | H9: Saisir 'admin123' dans Password | J9: La valeur est masquée | K9: Le mot de passe est masqué (invisible) | L9: Réussi
G10: 3 | H10: Cliquer sur Login | J10: L'alerte 'Invalid credentials' s'affiche ; l'URL contient toujours '/auth/login' | K10: Le message « Invalid credentials » s'affiche et l'utilisateur reste sur la page de connexion | L10: Réussi
C11: TC-004 | D11: Connexion avec un mot de passe dans la mauvaise casse | E11: fonctionnel | F11: Chrome (dernière version stable) ouvert sur la page de connexion de la démo ; aucun utilisateur connecté. | G11: 1 | H11: Saisir 'Admin' dans Username | I11: Username : Admin Password : ADMIN123 (mauvaise casse) | J11: La valeur s'affiche | K11: Username 'Admin' s'affiche correctement | L11: Réussi | M11: REQ-002 | N11: SC-002 | O11: Vérifier que le mot de passe est sensible à la casse. | P11: Moyenne | Q11: Estimation d'erreurs
G12: 2 | H12: Saisir 'ADMIN123' dans Password | J12: La valeur est masquée | K12: Le mot de passe est masqué (invisible) | L12: Réussi
G13: 3 | H13: Cliquer sur Login | J13: L'alerte 'Invalid credentials' s'affiche ; l'utilisateur reste sur la page de connexion | K13: Le message « Invalid credentials » s'affiche et l'utilisateur reste sur la page de connexion | L13: Réussi
C14: TC-005 | D14: Connexion avec Username vide | E14: fonctionnel | F14: Chrome (dernière version stable) ouvert sur la page de connexion de la démo ; aucun utilisateur connecté. | G14: 1 | H14: Laisser Username vide et saisir 'admin123' dans Password | I14: Username : (vide) Password : admin123 | J14: La valeur est masquée | K14: Le champ Username est vide et le mot de passe est masqué | L14: Réussi | M14: REQ-003 | N14: SC-003 | O14: Vérifier que Username est obligatoire (règle R5 de la table de décision). | P14: Haute | Q14: Test par tables de décision
G15: 2 | H15: Cliquer sur Login | J15: 'Required' s'affiche sous Username ; aucune alerte 'Invalid credentials' ; l'URL contient toujours '/auth/login' | K15: Le message « Required » s'affiche sous le champ Username et l'utilisateur reste sur la page de connexion. | L15: Réussi
C16: TC-006 | D16: Connexion avec Password vide | E16: fonctionnel | F16: Chrome (dernière version stable) ouvert sur la page de connexion de la démo ; aucun utilisateur connecté. | G16: 1 | H16: Saisir 'Admin' dans Username et laisser Password vide | I16: Username : Admin Password : (vide) | J16: La valeur s'affiche | K16: Username 'Admin' s'affiche correctement et la case mot de passe est vide | L16: Réussi | M16: REQ-003 | N16: SC-003 | O16: Vérifier que Password est obligatoire (règle R6 de la table de décision). | P16: Haute | Q16: Test par tables de décision
G17: 2 | H17: Cliquer sur Login | J17: 'Required' s'affiche sous Password et l'utilisateur reste sur la page de connexion | K17: 'Required' s'affiche sous Password et l'utilisateur reste sur la page de connexion | L17: Réussi
C18: TC-007 | D18: Connexion avec les deux champs vides | E18: fonctionnel | F18: Chrome (dernière version stable) ouvert sur la page de connexion de la démo ; aucun utilisateur connecté. | G18: 1 | H18: Cliquer sur Login sans rien saisir | I18: Username : (vide) Password : (vide) | J18: 'Required' s'affiche sous Username ET sous Password ; l'utilisateur reste sur la page de connexion | K18: 'Required' s'affiche sous Username et sous Password, et l'utilisateur reste sur la page de connexion | L18: Réussi | M18: REQ-003 | N18: SC-003 | O18: Vérifier que les deux messages d'obligation s'affichent ensemble (règle R7 de la table de décision). | P18: Moyenne | Q18: Test par tables de décision
C19: TC-008 | D19: Déconnexion depuis le menu déroulant de l'utilisateur | E19: fonctionnel | F19: Connecté en tant qu'Admin (Admin / admin123). | G19: 1 | H19: Cliquer sur le nom/l'avatar de l'utilisateur en haut à droite | I19: Session : Admin / admin123 Action : menu utilisateur → Logout | J19: Un menu déroulant contenant 'Logout' s'affiche | K19: Un menu déroulant s'affiche avec l'option Logout. | L19: Réussi | M19: REQ-005 | N19: SC-004 | O19: Vérifier la transition Authentifié -> Déconnecté. | P19: Haute | Q19: Test de transition d'états
G20: 2 | H20: Cliquer sur 'Logout' | J20: L'URL contient '/auth/login' ; le formulaire de connexion (Username, Password, Login) s'affiche | K20: Après avoir cliqué sur « Logout », l'utilisateur est déconnecté et redirigé vers la page de connexion. | L20: Réussi
C21: TC-009 | D21: Le bouton Retour du navigateur après déconnexion ne rouvre pas les pages internes | E21: fonctionnel | F21: Connecté en tant qu'Admin (Admin / admin123). | G21: 1 | H21: Cliquer sur PIM dans le menu principal | I21: Session : Admin / admin123 Module ouvert : PIM (Employee Information) Actions : Logout ; bouton Retour du navigateur ; actualisation (F5 dans l'étape, Ctrl + R dans le résultat obtenu) | J21: La liste Employee Information s'affiche | K21: La page « Employee Information » s'affiche correctement avec la liste des employés. | L21: Réussi | M21: REQ-006 | N21: SC-004 | O21: Vérifier la transition invalide Déconnecté -> page interne. | P21: Haute | Q21: Test de transition d'états
G22: 2 | H22: Se déconnecter (menu déroulant de l'utilisateur > Logout) | J22: La page de connexion s'affiche | K22: Après déconnexion, l'utilisateur est redirigé vers la page Login (/auth/login). | L22: Réussi
G23: 3 | H23: Cliquer sur le bouton Retour du navigateur, puis appuyer sur F5 (actualiser) | J23: La page de connexion s'affiche (l'URL contient '/auth/login') ; la liste Employee Information ne s'affiche pas | K23: Après Retour, l'ancienne page Employee List réapparaît. Après Ctrl + R, l'utilisateur est redirigé vers Login. L'accès direct à PIM est également refusé après déconnexion. | L23: Réussi
C24: TC-010 | D24: URL directe vers une page interne sans session | E24: fonctionnel | F24: Fenêtre de navigation privée Chrome (aucune session). | G24: 1 | H24: Coller l'URL dans la barre d'adresse et appuyer sur Entrée | I24: URL : https://opensource-demo.orangehrmlive.com/web/index.php/pim/viewEmployeeList Navigateur : Chrome, navigation privée (aucune session) | J24: Le navigateur est redirigé vers une URL contenant '/auth/login' ; le formulaire de connexion s'affiche ; aucune donnée d'employé n'est visible | K24: En navigation privée, l'accès direct à la page Employee List entraîne une redirection vers /auth/login. Le formulaire de connexion s'affiche et aucune donnée d'employé n'est visible. | L24: Réussi | M24: REQ-006 | N24: SC-004 | O24: Vérifier que la transition Non authentifié -> page protégée est redirigée. | P24: Haute | Q24: Test de transition d'états
C25: TC-011 | D25: Connexion avec un compte désactivé (Disabled) | E25: fonctionnel | F25: SETUP-01 effectué : employé de test « Ali Klayw » créé (ID : 0454). SETUP-02 effectué : compte ESS « qa.ali.klayw1020 » créé avec Status = Disabled. Admin déconnecté ; page Login affichée. | G25: 1 | H25: Saisir Username 'qa.ali.klayw1020' et Password 'QaTest@2026!' | I25: Username : qa.ali.klayw1020 Password : QaTest@2026! Status du compte : Disabled Employé associé : Ali Klayw (ID 0454) | J25: La valeur de Username s'affiche et le Password est masqué | K25: Le Username est saisi et le Password est masqué | L25: Réussi | M25: REQ-007 | N25: SC-005 | O25: Vérifier qu'un compte désactivé ne peut pas se connecter (table de décision : identifiants valides + statut Disabled). | P25: Haute | Q25: Test par tables de décision
G26: 2 | H26: Cliquer sur Login | J26: Le message 'Account disabled' s'affiche ; l'URL contient toujours '/auth/login' | K26: Le message « Account disabled » s'affiche ; l'accès au Dashboard est refusé et le formulaire Login reste affiché. | L26: Réussi
C27: TC-012 | D27: Réactiver un utilisateur désactivé puis se connecter | E27: fonctionnel | F27: SETUP-01 effectué ; SETUP-02 effectué avec Status = Disabled ; Connecté en tant qu'Admin (Admin / admin123). | G27: 1 | H27: Admin > User Management > Users ; rechercher le Username 'qa.ali.klayw1020' | I27: Test bloqué – aucune donnée d'exécution. Données prévues : Username = qa.ali.klayw1020 (compte introuvable) ; nouveau Status = Enabled ; Password = QaTest@2026 (à vérifier : « QaTest@2026! » en TC-011) | J27: Un seul enregistrement correspondant au compte « qa.ali.klayw1020 » s'affiche avec le statut « Disabled ». | K27: Test non exécuté : le compte de test « qa.ali.klayw1020 », précédemment créé avec le statut « Disabled », est introuvable dans Admin → Users. L'employé associé « Ali Klayw » est également introuvable dans PIM. Précondition non satisfaite. | L27: Bloqué | M27: REQ-017, REQ-007 | N27: SC-005 | O27: Vérifier que la transition Disabled -> Enabled rétablit l'accès. | P27: Haute | Q27: Test de transition d'états
G28: 2 | H28: Cliquer sur l'icône de modification (crayon) ; définir Status = Enabled ; Save | J28: Le compte est modifié avec succès et son statut devient « Enabled ». | K28: Étape non exécutée : impossible de modifier le statut du compte, car aucun utilisateur correspondant n'a été trouvé lors de la recherche précédente. | L28: Bloqué
G29: 3 | H29: Se déconnecter, puis se connecter avec 'qa.ali.klayw1020' / 'QaTest@2026' | J29: L'utilisateur se connecte avec succès et accède au Dashboard. | K29: Étape non exécutée : la connexion avec un compte activé n'a pas pu être vérifiée, car l'activation du compte était impossible. | L29: Bloqué
C30: TC-013 | D30: Ouvrir la page de demande de réinitialisation du mot de passe | E30: fonctionnel | F30: Chrome (dernière version stable) ouvert sur la page de connexion de la démo ; aucun utilisateur connecté. | G30: 1 | H30: Cliquer sur 'Forgot your password?' | I30: N/A – aucune saisie (lien « Forgot your password? ») | J30: L'URL contient '/auth/requestPasswordResetCode' ; le titre 'Reset Password' et un champ Username s'affichent | K30: Après avoir cliqué sur « Forgot your password? », le navigateur affiche la page « Reset Password ». L'URL contient « /auth/requestPasswordResetCode ». Le champ « Username » ainsi que les boutons « Cancel » et « Reset Password » sont visibles. | L30: Réussi | M30: REQ-008 | N30: SC-006 | O30: Vérifier le lien 'Forgot your password?'. | P30: Basse | Q30: Partitionnement en classes d'équivalence
B31: TS-02 Dashboard (tableau de bord) | C31: TC-014 | D31: Widgets du Dashboard affichés après la connexion | E31: fonctionnel | F31: Connecté en tant qu'Admin (Admin / admin123). | G31: 1 | H31: Cliquer sur Dashboard dans le menu principal | I31: Session : Admin / admin123 Aucune saisie (lecture des widgets) | J31: La page Dashboard s'affiche | K31: Après avoir cliqué sur « Dashboard » dans le menu principal, la page Dashboard s'affiche correctement. Le menu « Dashboard » est sélectionné et plusieurs widgets sont visibles. | L31: Réussi | M31: REQ-009 | N31: SC-007 | O31: Vérifier que les widgets documentés s'affichent. | P31: Basse | Q31: Test basé sur des checklists
G32: 2 | H32: Lire les titres des widgets | J32: Titres affichés : Time at Work, My Actions, Quick Launch, Buzz Latest Posts, Employees on Leave Today, Employee Distribution by Sub Unit, Employee Distribution by Location (consigner toute différence comme observation) | K32: Les sept widgets attendus sont affichés sur le Dashboard : Time at Work, My Actions, Quick Launch, Buzz Latest Posts, Employees on Leave Today, Employee Distribution by Sub Unit et Employee Distribution by Location. Aucune différence constatée. | L32: Réussi
B33: TS-03 Admin - Gestion des utilisateurs (User Management) | C33: TC-015 | D33: Créer un utilisateur ESS avec des données valides | E33: fonctionnel | F33: SETUP-01 effectué : employée de test « Nada Hakam » créée dans PIM ; connecté en tant qu'Admin (Admin / admin123) ; Admin → User Management → Users → + Add (formulaire Add User affiché). | G33: 1 | H33: Sélectionner User Role = ESS | I33: User Role : ESS Employee Name : Nada Hakam (saisie « Nada ») Status : Enabled Username : qa.nada.haka1020 Password / Confirm Password : QaTest@2026 | J33: « ESS » s'affiche dans le champ User Role. | K33: Le rôle « ESS » a été sélectionné dans le formulaire Add User. | L33: Réussi | M33: REQ-010 | N33: SC-008 | O33: Vérifier qu'un utilisateur système valide est créé. | P33: Haute | Q33: Partitionnement en classes d'équivalence
G34: 2 | H34: Saisir « Nada » dans Employee Name et sélectionner « Nada Hakam » dans la liste. | J34: « Nada Hakam » s'affiche dans le champ Employee Name ; aucun message « Invalid » n'apparaît. | K34: L'employée « Nada Hakam » a été sélectionnée dans le champ Employee Name, sans erreur de validation signalée. | L34: Réussi
G35: 3 | H35: Sélectionner Status = Enabled. | J35: « Enabled » s'affiche dans le champ Status. | K35: Le statut « Enabled » a été sélectionné pour le nouveau compte utilisateur. | L35: Réussi
G36: 4 | H36: Saisir le Username « qa.nada.haka1020 ». | J36: Le Username « qa.nada.haka1020 » est accepté sans message de validation. | K36: Le nom d'utilisateur « qa.nada.haka1020 » a été saisi et accepté lors de la création du compte. | L36: Réussi
G37: 5 | H37: Saisir 'QaTest@2026' dans Password et Confirm Password | J37: Aucun message de validation n'apparaît sous les deux champs. | K37: Le mot de passe et sa confirmation ont été renseignés ; la création du compte a pu être effectuée. | L37: Réussi
G38: 6 | H38: Cliquer sur Save | J38: Le message « Successfully Saved » s'affiche et la liste System Users apparaît. | K38: Le compte utilisateur a été enregistré avec succès et apparaît dans la liste System Users. | L38: Réussi
G39: 7 | H39: Rechercher le Username « qa.nada.haka1020 ». | J39: « (1) Record Found » ; la ligne indique Username « qa.nada.haka1020 », User Role « ESS », Employee Name « Nada Hakam » et Status « Enabled ». | K39: La recherche affiche « (1) Record Found » : Username « qa.nada.haka1020 », rôle « ESS », employée « Nada Hakam », statut « Enabled ». | L39: Réussi
C40: TC-016 | D40: Enregistrer le formulaire Add User vide | E40: fonctionnel | F40: Connecté en tant qu'Admin ; Admin > User Management > Users > + Add (formulaire Add User affiché). | G40: 1 | H40: Cliquer sur Save sans remplir aucun champ | I40: Tous les champs vides (User Role, Employee Name, Status, Username, Password, Confirm Password) | J40: 'Required' sous User Role, Employee Name, Status, Username et Password ; 'Passwords do not match' sous Confirm Password ; le formulaire Add User reste affiché | K40: Après avoir cliqué sur « Save » sans renseigner aucun champ, le message « Required » s'affiche sous User Role, Employee Name, Status, Username et Password. Le message « Passwords do not match » s'affiche sous Confirm Password. Le formulaire « Add User » reste affiché et aucun utilisateur n'est créé. | L40: Réussi | M40: REQ-010 | N40: SC-008 | O40: Vérifier que tous les champs obligatoires sont contrôlés. | P40: Haute | Q40: Partitionnement en classes d'équivalence
...

Sheet Exigences
A1: ID REQ | B1: Module | C1: Titre | D1: Exigence | E1: Base (D/A) | F1: Priorité | G1: Nb scénarios | H1: Nb cas de test | I1: Couverture | J1: ID scénarios | K1: ID cas de test
A2: REQ-001 | B2: Authentification (Login / Logout) | C2: Connexion réussie | D2: Le système doit authentifier un utilisateur qui saisit un Username et un Password valides, puis ouvrir le Dashboard. | E2: D/A | F2: Haute | G2: =COUNTIF(Scénarios!$C$2:$C$14,"*"&A2&"*") -> 1 | H2: =COUNTIF(Index_CT!$D$2:$D$36,"*"&A2&"*") -> 1 | I2: =IF(AND(G2>0,H2>0),"Couverte","NON COUVERTE") -> Couverte | J2: SC-001 | K2: TC-001
A3: REQ-002 | B3: Authentification (Login / Logout) | C3: Identifiants invalides refusés | D3: Si la paire Username/Password est invalide, le système doit maintenir l'utilisateur sur la page de connexion et afficher l'alerte 'Invalid credentials'. | E3: D | F3: Haute | G3: =COUNTIF(Scénarios!$C$2:$C$14,"*"&A3&"*") -> 1 | H3: =COUNTIF(Index_CT!$D$2:$D$36,"*"&A3&"*") -> 3 | I3: =IF(AND(G3>0,H3>0),"Couverte","NON COUVERTE") -> Couverte | J3: SC-002 | K3: TC-002, TC-003, TC-004
A4: REQ-003 | B4: Authentification (Login / Logout) | C4: Champs de connexion obligatoires | D4: Username et Password sont obligatoires. Un champ vide doit afficher 'Required' sous ce champ et le formulaire ne doit pas être soumis. | E4: D | F4: Haute | G4: =COUNTIF(Scénarios!$C$2:$C$14,"*"&A4&"*") -> 1 | H4: =COUNTIF(Index_CT!$D$2:$D$36,"*"&A4&"*") -> 3 | I4: =IF(AND(G4>0,H4>0),"Couverte","NON COUVERTE") -> Couverte | J4: SC-003 | K4: TC-005, TC-006, TC-007
A5: REQ-004 | B5: Authentification (Login / Logout) | C5: Masquage du mot de passe | D5: Le champ Password doit masquer les caractères saisis. | E5: D | F5: Moyenne | G5: =COUNTIF(Scénarios!$C$2:$C$14,"*"&A5&"*") -> 1 | H5: =COUNTIF(Index_CT!$D$2:$D$36,"*"&A5&"*") -> 1 | I5: =IF(AND(G5>0,H5>0),"Couverte","NON COUVERTE") -> Couverte | J5: SC-001 | K5: TC-001
A6: REQ-005 | B6: Authentification (Login / Logout) | C6: Déconnexion | D6: La sélection de Logout dans le menu déroulant de l'utilisateur doit mettre fin à la session et rediriger vers la page de connexion. | E6: D | F6: Haute | G6: =COUNTIF(Scénarios!$C$2:$C$14,"*"&A6&"*") -> 1 | H6: =COUNTIF(Index_CT!$D$2:$D$36,"*"&A6&"*") -> 1 | I6: =IF(AND(G6>0,H6>0),"Couverte","NON COUVERTE") -> Couverte | J6: SC-004 | K6: TC-008
A7: REQ-006 | B7: Authentification (Login / Logout) | C7: Pages protégées soumises à une session | D7: Sans session authentifiée (jamais connecté ou après déconnexion), toute demande d'une page interne doit rediriger vers la page de connexion. | E7: A | F7: Haute | G7: =COUNTIF(Scénarios!$C$2:$C$14,"*"&A7&"*") -> 1 | H7: =COUNTIF(Index_CT!$D$2:$D$36,"*"&A7&"*") -> 2 | I7: =IF(AND(G7>0,H7>0),"Couverte","NON COUVERTE") -> Couverte | J7: SC-004 | K7: TC-009, TC-010
A8: REQ-007 | B8: Authentification (Login / Logout) | C8: Compte désactivé sans accès | D8: Un utilisateur dont le statut est Disabled ne doit pas être authentifié ; le message 'Account disabled' doit s'afficher. | E8: D | F8: Haute | G8: =COUNTIF(Scénarios!$C$2:$C$14,"*"&A8&"*") -> 1 | H8: =COUNTIF(Index_CT!$D$2:$D$36,"*"&A8&"*") -> 2 | I8: =IF(AND(G8>0,H8>0),"Couverte","NON COUVERTE") -> Couverte | J8: SC-005 | K8: TC-011, TC-012
A9: REQ-008 | B9: Authentification (Login / Logout) | C9: Accès au mot de passe oublié | D9: Le lien 'Forgot your password?' doit ouvrir la page de demande de réinitialisation (/auth/requestPasswordResetCode). | E9: D | F9: Basse | G9: =COUNTIF(Scénarios!$C$2:$C$14,"*"&A9&"*") -> 1 | H9: =COUNTIF(Index_CT!$D$2:$D$36,"*"&A9&"*") -> 1 | I9: =IF(AND(G9>0,H9>0),"Couverte","NON COUVERTE") -> Couverte | J9: SC-006 | K9: TC-013
A10: REQ-009 | B10: Dashboard (tableau de bord) | C10: Widgets du Dashboard | D10: Après la connexion, le Dashboard doit afficher ses widgets : Time at Work, My Actions, Quick Launch, Buzz Latest Posts, Employees on Leave Today, Employee Distribution by Sub Unit, Employee Distribution by Location. | E10: D/A | F10: Basse | G10: =COUNTIF(Scénarios!$C$2:$C$14,"*"&A10&"*") -> 1 | H10: =COUNTIF(Index_CT!$D$2:$D$36,"*"&A10&"*") -> 1 | I10: =IF(AND(G10>0,H10>0),"Couverte","NON COUVERTE") -> Couverte | J10: SC-007 | K10: TC-014
A11: REQ-010 | B11: Admin - Gestion des utilisateurs (User Management) | C11: Ajout d'un utilisateur système | D11: Un Admin doit pouvoir créer un utilisateur système avec User Role (Admin/ESS), Employee Name, Status (Enabled/Disabled), Username, Password et Confirm Password, tous obligatoires. En cas de succès : message 'Successfully Saved' et retour à la liste System Users. | E11: D | F11: Haute | G11: =COUNTIF(Scénarios!$C$2:$C$14,"*"&A11&"*") -> 1 | H11: =COUNTIF(Index_CT!$D$2:$D$36,"*"&A11&"*") -> 2 | I11: =IF(AND(G11>0,H11>0),"Couverte","NON COUVERTE") -> Couverte | J11: SC-008 | K11: TC-015, TC-016
A12: REQ-011 | B12: Admin - Gestion des utilisateurs (User Management) | C12: Longueur du nom d'utilisateur | D12: Le Username doit comporter de 5 à 40 caractères. Moins de 5 : 'Should be at least 5 characters'. Plus de 40 : 'Should not exceed 40 characters'. | E12: D | F12: Haute | G12: =COUNTIF(Scénarios!$C$2:$C$14,"*"&A12&"*") -> 1 | H12: =COUNTIF(Index_CT!$D$2:$D$36,"*"&A12&"*") -> 4 | I12: =IF(AND(G12>0,H12>0),"Couverte","NON COUVERTE") -> Couverte | J12: SC-009 | K12: TC-018, TC-019, TC-020, TC-021
A13: REQ-012 | B13: Admin - Gestion des utilisateurs (User Management) | C13: Unicité du nom d'utilisateur | D13: Un nom d'utilisateur déjà utilisé doit être refusé avec 'Already exists'. | E13: D | F13: Haute | G13: =COUNTIF(Scénarios!$C$2:$C$14,"*"&A13&"*") -> 1 | H13: =COUNTIF(Index_CT!$D$2:$D$36,"*"&A13&"*") -> 1 | I13: =IF(AND(G13>0,H13>0),"Couverte","NON COUVERTE") -> Couverte | J13: SC-009 | K13: TC-022
... A20: REQ-019 | B20: Admin - Gestion des utilisateurs (User Management) | C20: Menu selon le rôle | D20: Le menu principal doit dépendre du rôle de l'utilisateur : un Admin voit Admin et PIM ; un utilisateur ESS ne voit ni Admin ni PIM. | E20: A | F20: Haute | G20: =COUNTIF(Scénarios!$C$2:$C$14,"*"&A20&"*") -> 1 | H20: =COUNTIF(Index_CT!$D$2:$D$36,"*"&A20&"*") -> 2 | I20: =IF(AND(G20>0,H20>0),"Couverte","NON COUVERTE") -> Couverte | J20: SC-013 | K20: TC-034, TC-035

Sheet Scénarios
A1: ID scénario | B1: Module | C1: ID exigence(s) | D1: Description | E1: Type | F1: Priorité | G1: Technique | H1: Justification de la priorité | I1: Nb cas de test | J1: ID cas de test
A2: SC-001 | B2: Authentification (Login / Logout) | C2: REQ-001, REQ-004 | D2: Se connecter avec des identifiants valides | E2: Positif | F2: Haute | G2: Test par tables de décision | H2: Point d'entrée de tous les modules ; bloque tous les autres tests en cas de défaillance. | I2: =COUNTIF(Index_CT!$C$2:$C$36,A2) -> 1 | J2: TC-001
A3: SC-002 | B3: Authentification (Login / Logout) | C3: REQ-002 | D3: Connexion refusée pour des combinaisons d'identifiants invalides | E3: Négatif | F3: Haute | G3: Test par tables de décision, Estimation d'erreurs | H3: Risque de sécurité : accès non autorisé. | I3: =COUNTIF(Index_CT!$C$2:$C$36,A3) -> 3 | J3: TC-002, TC-003, TC-004
A4: SC-003 | B4: Authentification (Login / Logout) | C4: REQ-003 | D4: Connexion refusée lorsque des champs obligatoires sont vides | E4: Négatif | F4: Haute | G4: Test par tables de décision | H4: Erreur utilisateur fréquente ; premier niveau de validation. | I4: =COUNTIF(Index_CT!$C$2:$C$36,A4) -> 3 | J4: TC-005, TC-006, TC-007
A5: SC-004 | B5: Authentification (Login / Logout) | C5: REQ-005, REQ-006 | D5: Déconnexion et accès aux pages protégées sans session | E5: Positif / Négatif | F5: Haute | G5: Test de transition d'états | H5: Une fuite de session expose des données personnelles RH. | I5: =COUNTIF(Index_CT!$C$2:$C$36,A5) -> 3 | J5: TC-008, TC-009, TC-010
A6: SC-005 | B6: Authentification (Login / Logout) | C6: REQ-007, REQ-017 | D6: Le statut du compte (Enabled/Disabled) conditionne la connexion | E6: Positif / Négatif | F6: Haute | G6: Test de transition d'états, Test par tables de décision | H6: Les comptes désactivés (salariés sortis) ne doivent pas accéder aux données RH. | I6: =COUNTIF(Index_CT!$C$2:$C$36,A6) -> 2 | J6: TC-011, TC-012
A7: SC-006 | B7: Authentification (Login / Logout) | C7: REQ-008 | D7: Accéder à la page de demande de réinitialisation du mot de passe | E7: Positif | F7: Basse | G7: Partitionnement en classes d'équivalence | H7: Lien de navigation à faible impact ; l'envoi d'e-mail est hors périmètre. | I7: =COUNTIF(Index_CT!$C$2:$C$36,A7) -> 1 | J7: TC-013
A8: SC-007 | B8: Dashboard (tableau de bord) | C8: REQ-009 | D8: Les widgets du Dashboard s'affichent après la connexion | E8: Positif | F8: Basse | G8: Test basé sur des checklists | H8: Affichage d'information uniquement ; niveau smoke test. | I8: =COUNTIF(Index_CT!$C$2:$C$36,A8) -> 1 | J8: TC-014
A9: SC-008 | B9: Admin - Gestion des utilisateurs (User Management) | C9: REQ-010, REQ-015 | D9: Créer un utilisateur système (formulaire valide et invalide) | E9: Positif / Négatif | F9: Haute | G9: Partitionnement en classes d'équivalence | H9: La création de comptes détermine les droits d'accès. | I9: =COUNTIF(Index_CT!$C$2:$C$36,A9) -> 3 | J9: TC-015, TC-016, TC-017
A10: SC-009 | B10: Admin - Gestion des utilisateurs (User Management) | C10: REQ-011, REQ-012 | D10: Validation de la longueur et de l'unicité du nom d'utilisateur | E10: Limite / Négatif | F10: Haute | G10: Analyse des valeurs limites, Partitionnement en classes d'équivalence | H10: Limites documentées 5-40 ; les doublons perturbent l'authentification. | I10: =COUNTIF(Index_CT!$C$2:$C$36,A10) -> 5 | J10: TC-018, TC-019, TC-020, TC-021, TC-022
A11: SC-010 | B11: Admin - Gestion des utilisateurs (User Management) | C11: REQ-013, REQ-014 | D11: Confirmation du mot de passe et politique de mot de passe | E11: Négatif / Limite | F11: Haute | G11: Analyse des valeurs limites, Partitionnement en classes d'équivalence | H11: Mots de passe faibles = risque de sécurité. | I11: =COUNTIF(Index_CT!$C$2:$C$36,A11) -> 5 | J11: TC-023, TC-024, TC-025, TC-026, TC-027
A12: SC-011 | B12: Admin - Gestion des utilisateurs (User Management) | C12: REQ-016 | D12: Rechercher des utilisateurs système et réinitialiser les filtres | E12: Positif / Négatif | F12: Moyenne | G12: Partitionnement en classes d'équivalence | H12: Efficacité administrative ; aucune modification de données. | I12: =COUNTIF(Index_CT!$C$2:$C$36,A12) -> 3 | J12: TC-028, TC-029, TC-030
A13: SC-012 | B13: Admin - Gestion des utilisateurs (User Management) | C13: REQ-018 | D13: Supprimer un utilisateur système (confirmation, annulation, auto-suppression interdite) | E13: Positif / Négatif | F13: Haute | G13: Test de transition d'états, Estimation d'erreurs | H13: Action irréversible ; l'auto-suppression bloquerait l'administrateur. | I13: =COUNTIF(Index_CT!$C$2:$C$36,A13) -> 3 | J13: TC-031, TC-032, TC-033
A14: SC-013 | B14: Admin - Gestion des utilisateurs (User Management) | C14: REQ-019 | D14: Le menu principal dépend du rôle de l'utilisateur | E14: Positif / Négatif | F14: Haute | G14: Partitionnement en classes d'équivalence | H14: Risque d'élévation de privilèges. | I14: =COUNTIF(Index_CT!$C$2:$C$36,A14) -> 2 | J14: TC-034, TC-035

Sheet Index_CT
A1: ID CT | B1: Titre | C1: ID scénario | D1: ID exigence(s) | E1: Module | F1: Priorité | G1: Technique | H1: Type | I1: Statut | J1: Nb REQ liées | K1: Scénario existant | L1: ID REQ valides | M1: REQ dans le scénario | N1: Présent dans Sheet2 (nb)
A2: TC-001 | B2: Connexion avec des identifiants Admin valides | C2: SC-001 | D2: REQ-001, REQ-004 | E2: Authentification (Login / Logout) | F2: Haute | G2: Test par tables de décision | H2: Positif | I2: Réussi | J2: =IF(D2="",0,LEN(D2)-LEN(SUBSTITUTE(D2,",",""))+1) -> 2 | K2: =IF(COUNTIF(Scénarios!$A$2:$A$14,C2)=1,"OK","MANQUANT") -> OK | L2: =IF(SUMPRODUCT(ISNUMBER(SEARCH(Exigences!$A$2:$A$20,D2))*1)=J2,"OK","INCONNU") -> OK | M2: =IF(SUMPRODUCT(ISNUMBER(SEARCH(Exigences!$A$2:$A$20,D2))*ISNUMBER(SEARCH(Exigences!$A$2:$A$20,INDEX(Scénarios!$C$2:$C$14,MATCH(C2,Scénarios!$A$2:$A$14,0)))))=J2,"OK","À VÉRIFIER") -> OK | N2: =COUNTIF(Sheet2!$C$2:$C$71,A2) -> 1
A3: TC-002 | B3: Connexion avec un nom d'utilisateur valide et un mot de passe erroné | C3: SC-002 | D3: REQ-002 | E3: Authentification (Login / Logout) | F3: Haute | G3: Test par tables de décision | H3: Négatif | I3: Réussi | J3: =IF(D3="",0,LEN(D3)-LEN(SUBSTITUTE(D3,",",""))+1) -> 1 | K3: =IF(COUNTIF(Scénarios!$A$2:$A$14,C3)=1,"OK","MANQUANT") -> OK | L3: =IF(SUMPRODUCT(ISNUMBER(SEARCH(Exigences!$A$2:$A$20,D3))*1)=J3,"OK","INCONNU") -> OK | M3: =IF(SUMPRODUCT(ISNUMBER(SEARCH(Exigences!$A$2:$A$20,D3))*ISNUMBER(SEARCH(Exigences!$A$2:$A$20,INDEX(Scénarios!$C$2:$C$14,MATCH(C3,Scénarios!$A$2:$A$14,0)))))=J3,"OK","À VÉRIFIER") -> OK | N3: =COUNTIF(Sheet2!$C$2:$C$71,A3) -> 1
A4: TC-003 | B4: Connexion avec un nom d'utilisateur inconnu et un mot de passe valide | C4: SC-002 | D4: REQ-002 | E4: Authentification (Login / Logout) | F4: Haute | G4: Test par tables de décision | H4: Négatif | I4: Réussi | J4: =IF(D4="",0,LEN(D4)-LEN(SUBSTITUTE(D4,",",""))+1) -> 1 | K4: =IF(COUNTIF(Scénarios!$A$2:$A$14,C4)=1,"OK","MANQUANT") -> OK | L4: =IF(SUMPRODUCT(ISNUMBER(SEARCH(Exigences!$A$2:$A$20,D4))*1)=J4,"OK","INCONNU") -> OK | M4: =IF(SUMPRODUCT(ISNUMBER(SEARCH(Exigences!$A$2:$A$20,D4))*ISNUMBER(SEARCH(Exigences!$A$2:$A$20,INDEX(Scénarios!$C$2:$C$14,MATCH(C4,Scénarios!$A$2:$A$14,0)))))=J4,"OK","À VÉRIFIER") -> OK | N4: =COUNTIF(Sheet2!$C$2:$C$71,A4) -> 1
A5: TC-004 | B5: Connexion avec un mot de passe dans la mauvaise casse | C5: SC-002 | D5: REQ-002 | E5: Authentification (Login / Logout) | F5: Moyenne | G5: Estimation d'erreurs | H5: Négatif | I5: Réussi | J5: =IF(D5="",0,LEN(D5)-LEN(SUBSTITUTE(D5,",",""))+1) -> 1 | K5: =IF(COUNTIF(Scénarios!$A$2:$A$14,C5)=1,"OK","MANQUANT") -> OK | L5: =IF(SUMPRODUCT(ISNUMBER(SEARCH(Exigences!$A$2:$A$20,D5))*1)=J5,"OK","INCONNU") -> OK | M5: =IF(SUMPRODUCT(ISNUMBER(SEARCH(Exigences!$A$2:$A$20,D5))*ISNUMBER(SEARCH(Exigences!$A$2:$A$20,INDEX(Scénarios!$C$2:$C$14,MATCH(C5,Scénarios!$A$2:$A$14,0)))))=J5,"OK","À VÉRIFIER") -> OK | N5: =COUNTIF(Sheet2!$C$2:$C$71,A5) -> 1
A6: TC-005 | B6: Connexion avec Username vide | C6: SC-003 | D6: REQ-003 | E6: Authentification (Login / Logout) | F6: Haute | G6: Test par tables de décision | H6: Négatif | I6: Réussi | J6: =IF(D6="",0,LEN(D6)-LEN(SUBSTITUTE(D6,",",""))+1) -> 1 | K6: =IF(COUNTIF(Scénarios!$A$2:$A$14,C6)=1,"OK","MANQUANT") -> OK | L6: =IF(SUMPRODUCT(ISNUMBER(SEARCH(Exigences!$A$2:$A$20,D6))*1)=J6,"OK","INCONNU") -> OK | M6: =IF(SUMPRODUCT(ISNUMBER(SEARCH(Exigences!$A$2:$A$20,D6))*ISNUMBER(SEARCH(Exigences!$A$2:$A$20,INDEX(Scénarios!$C$2:$C$14,MATCH(C6,Scénarios!$A$2:$A$14,0)))))=J6,"OK","À VÉRIFIER") -> OK | N6: =COUNTIF(Sheet2!$C$2:$C$71,A6) -> 1
A7: TC-006 | B7: Connexion avec Password vide | C7: SC-003 | D7: REQ-003 | E7: Authentification (Login / Logout) | F7: Haute | G7: Test par tables de décision | H7: Négatif | I7: Réussi | J7: =IF(D7="",0,LEN(D7)-LEN(SUBSTITUTE(D7,",",""))+1) -> 1 | K7: =IF(COUNTIF(Scénarios!$A$2:$A$14,C7)=1,"OK","MANQUANT") -> OK | L7: =IF(SUMPRODUCT(ISNUMBER(SEARCH(Exigences!$A$2:$A$20,D7))*1)=J7,"OK","INCONNU") -> OK | M7: =IF(SUMPRODUCT(ISNUMBER(SEARCH(Exigences!$A$2:$A$20,D7))*ISNUMBER(SEARCH(Exigences!$A$2:$A$20,INDEX(Scénarios!$C$2:$C$14,MATCH(C7,Scénarios!$A$2:$A$14,0)))))=J7,"OK","À VÉRIFIER") -> OK | N7: =COUNTIF(Sheet2!$C$2:$C$71,A7) -> 1
A8: TC-007 | B8: Connexion avec les deux champs vides | C8: SC-003 | D8: REQ-003 | E8: Authentification (Login / Logout) | F8: Moyenne | G8: Test par tables de décision | H8: Négatif | I8: Réussi | J8: =IF(D8="",0,LEN(D8)-LEN(SUBSTITUTE(D8,",",""))+1) -> 1 | K8: =IF(COUNTIF(Scénarios!$A$2:$A$14,C8)=1,"OK","MANQUANT") -> OK | L8: =IF(SUMPRODUCT(ISNUMBER(SEARCH(Exigences!$A$2:$A$20,D8))*1)=J8,"OK","INCONNU") -> OK | M8: =IF(SUMPRODUCT(ISNUMBER(SEARCH(Exigences!$A$2:$A$20,D8))*ISNUMBER(SEARCH(Exigences!$A$2:$A$20,INDEX(Scénarios!$C$2:$C$14,MATCH(C8,Scénarios!$A$2:$A$14,0)))))=J8,"OK","À VÉRIFIER") -> OK | N8: =COUNTIF(Sheet2!$C$2:$C$71,A8) -> 1
A9: TC-008 | B9: Déconnexion depuis le menu déroulant de l'utilisateur | C9: SC-004 | D9: REQ-005 | E9: Authentification (Login / Logout) | F9: Haute | G9: Test de transition d'états | H9: Positif | I9: Réussi | J9: =IF(D9="",0,LEN(D9)-LEN(SUBSTITUTE(D9,",",""))+1) -> 1 | K9: =IF(COUNTIF(Scénarios!$A$2:$A$14,C9)=1,"OK","MANQUANT") -> OK | L9: =IF(SUMPRODUCT(ISNUMBER(SEARCH(Exigences!$A$2:$A$20,D9))*1)=J9,"OK","INCONNU") -> OK | M9: =IF(SUMPRODUCT(ISNUMBER(SEARCH(Exigences!$A$2:$A$20,D9))*ISNUMBER(SEARCH(Exigences!$A$2:$A$20,INDEX(Scénarios!$C$2:$C$14,MATCH(C9,Scénarios!$A$2:$A$14,0)))))=J9,"OK","À VÉRIFIER") -> OK | N9: =COUNTIF(Sheet2!$C$2:$C$71,A9) -> 1
A10: TC-009 | B10: Le bouton Retour du navigateur après déconnexion ne rouvre pas les pages internes | C10: SC-004 | D10: REQ-006 | E10: Authentification (Login / Logout) | F10: Haute | G10: Test de transition d'états | H10: Négatif | I10: Réussi | J10: =IF(D10="",0,LEN(D10)-LEN(SUBSTITUTE(D10,",",""))+1) -> 1 | K10: =IF(COUNTIF(Scénarios!$A$2:$A$14,C10)=1,"OK","MANQUANT") -> OK | L10: =IF(SUMPRODUCT(ISNUMBER(SEARCH(Exigences!$A$2:$A$20,D10))*1)=J10,"OK","INCONNU") -> OK | M10: =IF(SUMPRODUCT(ISNUMBER(SEARCH(Exigences!$A$2:$A$20,D10))*ISNUMBER(SEARCH(Exigences!$A$2:$A$20,INDEX(Scénarios!$C$2:$C$14,MATCH(C10,Scénarios!$A$2:$A$14,0)))))=J10,"OK","À VÉRIFIER") -> OK | N10: =COUNTIF(Sheet2!$C$2:$C$71,A10) -> 1
A11: TC-010 | B11: URL directe vers une page interne sans session | C11: SC-004 | D11: REQ-006 | E11: Authentification (Login / Logout) | F11: Haute | G11: Test de transition d'états | H11: Négatif | I11: Réussi | J11: =IF(D11="",0,LEN(D11)-LEN(SUBSTITUTE(D11,",",""))+1) -> 1 | K11: =IF(COUNTIF(Scénarios!$A$2:$A$14,C11)=1,"OK","MANQUANT") -> OK | L11: =IF(SUMPRODUCT(ISNUMBER(SEARCH(Exigences!$A$2:$A$20,D11))*1)=J11,"OK","INCONNU") -> OK | M11: =IF(SUMPRODUCT(ISNUMBER(SEARCH(Exigences!$A$2:$A$20,D11))*ISNUMBER(SEARCH(Exigences!$A$2:$A$20,INDEX(Scénarios!$C$2:$C$14,MATCH(C11,Scénarios!$A$2:$A$14,0)))))=J11,"OK","À VÉRIFIER") -> OK | N11: =COUNTIF(Sheet2!$C$2:$C$71,A11) -> 1
A12: TC-011 | B12: Connexion avec un compte désactivé (Disabled) | C12: SC-005 | D12: REQ-007 | E12: Authentification (Login / Logout) | F12: Haute | G12: Test par tables de décision | H12: Négatif | I12: Réussi | J12: =IF(D12="",0,LEN(D12)-LEN(SUBSTITUTE(D12,",",""))+1) -> 1 | K12: =IF(COUNTIF(Scénarios!$A$2:$A$14,C12)=1,"OK","MANQUANT") -> OK | L12: =IF(SUMPRODUCT(ISNUMBER(SEARCH(Exigences!$A$2:$A$20,D12))*1)=J12,"OK","INCONNU") -> OK | M12: =IF(SUMPRODUCT(ISNUMBER(SEARCH(Exigences!$A$2:$A$20,D12))*ISNUMBER(SEARCH(Exigences!$A$2:$A$20,INDEX(Scénarios!$C$2:$C$14,MATCH(C12,Scénarios!$A$2:$A$14,0)))))=J12,"OK","À VÉRIFIER") -> OK | N12: =COUNTIF(Sheet2!$C$2:$C$71,A12) -> 1
A13: TC-012 | B13: Réactiver un utilisateur désactivé puis se connecter | C13: SC-005 | D13: REQ-017, REQ-007 | E13: Authentification (Login / Logout) | F13: Haute | G13: Test de transition d'états | H13: Positif | I13: Bloqué | J13: =IF(D13="",0,LEN(D13)-LEN(SUBSTITUTE(D13,",",""))+1) -> 2 | K13: =IF(COUNTIF(Scénarios!$A$2:$A$14,C13)=1,"OK","MANQUANT") -> OK | L13: =IF(SUMPRODUCT(ISNUMBER(SEARCH(Exigences!$A$2:$A$20,D13))*1)=J13,"OK","INCONNU") -> OK | M13: =IF(SUMPRODUCT(ISNUMBER(SEARCH(Exigences!$A$2:$A$20,D13))*ISNUMBER(SEARCH(Exigences!$A$2:$A$20,INDEX(Scénarios!$C$2:$C$14,MATCH(C13,Scénarios!$A$2:$A$14,0)))))=J13,"OK","À VÉRIFIER") -> OK | N13: =COUNTIF(Sheet2!$C$2:$C$71,A13) -> 1
... A36: TC-035 | B36: Menu principal d'un utilisateur ESS | C36: SC-013 | D36: REQ-019 | E36: Admin - Gestion des utilisateurs (User Management) | F36: Haute | G36: Partitionnement en classes d'équivalence | H36: Négatif | I36: Bloqué | J36: =IF(D36="",0,LEN(D36)-LEN(SUBSTITUTE(D36,",",""))+1) -> 1 | K36: =IF(COUNTIF(Scénarios!$A$2:$A$14,C36)=1,"OK","MANQUANT") -> OK | L36: =IF(SUMPRODUCT(ISNUMBER(SEARCH(Exigences!$A$2:$A$20,D36))*1)=J36,"OK","INCONNU") -> OK | M36: =IF(SUMPRODUCT(ISNUMBER(SEARCH(Exigences!$A$2:$A$20,D36))*ISNUMBER(SEARCH(Exigences!$A$2:$A$20,INDEX(Scénarios!$C$2:$C$14,MATCH(C36,Scénarios!$A$2:$A$14,0)))))=J36,"OK","À VÉRIFIER") -> OK | N36: =COUNTIF(Sheet2!$C$2:$C$71,A36) -> 1

Sheet Matrice_Traçabilité
A1: Matrice de traçabilité bidirectionnelle - lignes : exigences (descendante REQ -> CT), colonnes : cas de test (ascendante CT -> REQ). Le 'X' est calculé à partir d'Index_CT.
D2: Scénario -> | E2: =INDEX(Index_CT!$C$2:$C$36,MATCH(E$3,Index_CT!$A$2:$A$36,0)) -> SC-001 | F2: =INDEX(Index_CT!$C$2:$C$36,MATCH(F$3,Index_CT!$A$2:$A$36,0)) -> SC-002 | G2: =INDEX(Index_CT!$C$2:$C$36,MATCH(G$3,Index_CT!$A$2:$A$36,0)) -> SC-002 | H2: =INDEX(Index_CT!$C$2:$C$36,MATCH(H$3,Index_CT!$A$2:$A$36,0)) -> SC-002 | I2: =INDEX(Index_CT!$C$2:$C$36,MATCH(I$3,Index_CT!$A$2:$A$36,0)) -> SC-003 | J2: =INDEX(Index_CT!$C$2:$C$36,MATCH(J$3,Index_CT!$A$2:$A$36,0)) -> SC-003 | K2: =INDEX(Index_CT!$C$2:$C$36,MATCH(K$3,Index_CT!$A$2:$A$36,0)) -> SC-003 | L2: =INDEX(Index_CT!$C$2:$C$36,MATCH(L$3,Index_CT!$A$2:$A$36,0)) -> SC-004 | ... BR2: =INDEX(Index_CT!$C$2:$C$36,MATCH(BR$3,Index_CT!$A$2:$A$36,0)) -> #N/A
A3: ID REQ | B3: Exigence | C3: Priorité | D3: Nb CT (descendante) | E3: TC-001 | F3: TC-002 | G3: TC-003 | H3: TC-004 | I3: TC-005 | J3: TC-006 | K3: TC-007 | L3: TC-008 | M3: TC-009 | N3: TC-010 | O3: TC-011 | P3: TC-012 | Q3: TC-013 | R3: TC-014 | S3: TC-015 | T3: TC-016 | U3: TC-017 | V3: TC-018 | W3: TC-019 | X3: TC-020 | Y3: TC-021 | Z3: TC-022 | AA3: TC-023 | AB3: TC-024 | AC3: TC-025 | AD3: TC-026 | AE3: TC-027 | AF3: TC-028 | AG3: TC-029 | AH3: TC-030 | AI3: TC-031 | AJ3: TC-032 | AK3: TC-033 | AL3: TC-034 | AM3: TC-035 | AN3: TC-036 | AO3: TC-037 | AP3: TC-038 | AQ3: TC-039 | AR3: TC-040 | AS3: TC-041 | AT3: TC-042 | AU3: TC-043 | AV3: TC-044 | AW3: TC-045 | AX3: TC-046 | AY3: TC-047 | AZ3: TC-048 | BA3: TC-049 | BB3: TC-050 | BC3: TC-051 | BD3: TC-052 | BE3: TC-053 | BF3: TC-054 | BG3: TC-055 | BH3: TC-056 | BI3: TC-057 | BJ3: TC-058 | BK3: TC-059 | BL3: TC-060 | BM3: TC-061 | BN3: TC-062 | BO3: TC-063 | BP3: TC-064 | BQ3: TC-065 | BR3: TC-066
A4: REQ-001 | B4: Connexion réussie | C4: Haute | D4: =COUNTIF(E4:BR4,"X") -> 1 | E4: =IF(ISNUMBER(SEARCH($A4,INDEX(Index_CT!$D$2:$D$36,MATCH(E$3,Index_CT!$A$2:$A$36,0)))),"X","") -> X | F4: =IF(ISNUMBER(SEARCH($A4,INDEX(Index_CT!$D$2:$D$36,MATCH(F$3,Index_CT!$A$2:$A$36,0)))),"X","") | G4: =IF(ISNUMBER(SEARCH($A4,INDEX(Index_CT!$D$2:$D$36,MATCH(G$3,Index_CT!$A$2:$A$36,0)))),"X","") | H4: =IF(ISNUMBER(SEARCH($A4,INDEX(Index_CT!$D$2:$D$36,MATCH(H$3,Index_CT!$A$2:$A$36,0)))),"X","") | I4: =IF(ISNUMBER(SEARCH($A4,INDEX(Index_CT!$D$2:$D$36,MATCH(I$3,Index_CT!$A$2:$A$36,0)))),"X","") | J4: =IF(ISNUMBER(SEARCH($A4,INDEX(Index_CT!$D$2:$D$36,MATCH(J$3,Index_CT!$A$2:$A$36,0)))),"X","") | K4: =IF(ISNUMBER(SEARCH($A4,INDEX(Index_CT!$D$2:$D$36,MATCH(K$3,Index_CT!$A$2:$A$36,0)))),"X","") | L4: =IF(ISNUMBER(SEARCH($A4,INDEX(Index_CT!$D$2:$D$36,MATCH(L$3,Index_CT!$A$2:$A$36,0)))),"X","") | ... BR4: =IF(ISNUMBER(SEARCH($A4,INDEX(Index_CT!$D$2:$D$36,MATCH(BR$3,Index_CT!$A$2:$A$36,0)))),"X","")
A5: REQ-002 | B5: Identifiants invalides refusés | C5: Haute | D5: =COUNTIF(E5:BR5,"X") -> 3 | E5: =IF(ISNUMBER(SEARCH($A5,INDEX(Index_CT!$D$2:$D$36,MATCH(E$3,Index_CT!$A$2:$A$36,0)))),"X","") | F5: =IF(ISNUMBER(SEARCH($A5,INDEX(Index_CT!$D$2:$D$36,MATCH(F$3,Index_CT!$A$2:$A$36,0)))),"X","") -> X | G5: =IF(ISNUMBER(SEARCH($A5,INDEX(Index_CT!$D$2:$D$36,MATCH(G$3,Index_CT!$A$2:$A$36,0)))),"X","") -> X | H5: =IF(ISNUMBER(SEARCH($A5,INDEX(Index_CT!$D$2:$D$36,MATCH(H$3,Index_CT!$A$2:$A$36,0)))),"X","") -> X | I5: =IF(ISNUMBER(SEARCH($A5,INDEX(Index_CT!$D$2:$D$36,MATCH(I$3,Index_CT!$A$2:$A$36,0)))),"X","") | J5: =IF(ISNUMBER(SEARCH($A5,INDEX(Index_CT!$D$2:$D$36,MATCH(J$3,Index_CT!$A$2:$A$36,0)))),"X","") | K5: =IF(ISNUMBER(SEARCH($A5,INDEX(Index_CT!$D$2:$D$36,MATCH(K$3,Index_CT!$A$2:$A$36,0)))),"X","") | L5: =IF(ISNUMBER(SEARCH($A5,INDEX(Index_CT!$D$2:$D$36,MATCH(L$3,Index_CT!$A$2:$A$36,0)))),"X","") | ... BR5: =IF(ISNUMBER(SEARCH($A5,INDEX(Index_CT!$D$2:$D$36,MATCH(BR$3,Index_CT!$A$2:$A$36,0)))),"X","")
A6: REQ-003 | B6: Champs de connexion obligatoires | C6: Haute | D6: =COUNTIF(E6:BR6,"X") -> 3 | E6: =IF(ISNUMBER(SEARCH($A6,INDEX(Index_CT!$D$2:$D$36,MATCH(E$3,Index_CT!$A$2:$A$36,0)))),"X","") | F6: =IF(ISNUMBER(SEARCH($A6,INDEX(Index_CT!$D$2:$D$36,MATCH(F$3,Index_CT!$A$2:$A$36,0)))),"X","") | G6: =IF(ISNUMBER(SEARCH($A6,INDEX(Index_CT!$D$2:$D$36,MATCH(G$3,Index_CT!$A$2:$A$36,0)))),"X","") | H6: =IF(ISNUMBER(SEARCH($A6,INDEX(Index_CT!$D$2:$D$36,MATCH(H$3,Index_CT!$A$2:$A$36,0)))),"X","") | I6: =IF(ISNUMBER(SEARCH($A6,INDEX(Index_CT!$D$2:$D$36,MATCH(I$3,Index_CT!$A$2:$A$36,0)))),"X","") -> X | J6: =IF(ISNUMBER(SEARCH($A6,INDEX(Index_CT!$D$2:$D$36,MATCH(J$3,Index_CT!$A$2:$A$36,0)))),"X","") -> X | K6: =IF(ISNUMBER(SEARCH($A6,INDEX(Index_CT!$D$2:$D$36,MATCH(K$3,Index_CT!$A$2:$A$36,0)))),"X","") -> X | L6: =IF(ISNUMBER(SEARCH($A6,INDEX(Index_CT!$D$2:$D$36,MATCH(L$3,Index_CT!$A$2:$A$36,0)))),"X","") | ... BR6: =IF(ISNUMBER(SEARCH($A6,INDEX(Index_CT!$D$2:$D$36,MATCH(BR$3,Index_CT!$A$2:$A$36,0)))),"X","")
A7: REQ-004 | B7: Masquage du mot de passe | C7: Moyenne | D7: =COUNTIF(E7:BR7,"X") -> 1 | E7: =IF(ISNUMBER(SEARCH($A7,INDEX(Index_CT!$D$2:$D$36,MATCH(E$3,Index_CT!$A$2:$A$36,0)))),"X","") -> X | F7: =IF(ISNUMBER(SEARCH($A7,INDEX(Index_CT!$D$2:$D$36,MATCH(F$3,Index_CT!$A$2:$A$36,0)))),"X","") | G7: =IF(ISNUMBER(SEARCH($A7,INDEX(Index_CT!$D$2:$D$36,MATCH(G$3,Index_CT!$A$2:$A$36,0)))),"X","") | H7: =IF(ISNUMBER(SEARCH($A7,INDEX(Index_CT!$D$2:$D$36,MATCH(H$3,Index_CT!$A$2:$A$36,0)))),"X","") | I7: =IF(ISNUMBER(SEARCH($A7,INDEX(Index_CT!$D$2:$D$36,MATCH(I$3,Index_CT!$A$2:$A$36,0)))),"X","") | J7: =IF(ISNUMBER(SEARCH($A7,INDEX(Index_CT!$D$2:$D$36,MATCH(J$3,Index_CT!$A$2:$A$36,0)))),"X","") | K7: =IF(ISNUMBER(SEARCH($A7,INDEX(Index_CT!$D$2:$D$36,MATCH(K$3,Index_CT!$A$2:$A$36,0)))),"X","") | L7: =IF(ISNUMBER(SEARCH($A7,INDEX(Index_CT!$D$2:$D$36,MATCH(L$3,Index_CT!$A$2:$A$36,0)))),"X","") | ... BR7: =IF(ISNUMBER(SEARCH($A7,INDEX(Index_CT!$D$2:$D$36,MATCH(BR$3,Index_CT!$A$2:$A$36,0)))),"X","")
A8: REQ-005 | B8: Déconnexion | C8: Haute | D8: =COUNTIF(E8:BR8,"X") -> 1 | E8: =IF(ISNUMBER(SEARCH($A8,INDEX(Index_CT!$D$2:$D$36,MATCH(E$3,Index_CT!$A$2:$A$36,0)))),"X","") | F8: =IF(ISNUMBER(SEARCH($A8,INDEX(Index_CT!$D$2:$D$36,MATCH(F$3,Index_CT!$A$2:$A$36,0)))),"X","") | G8: =IF(ISNUMBER(SEARCH($A8,INDEX(Index_CT!$D$2:$D$36,MATCH(G$3,Index_CT!$A$2:$A$36,0)))),"X","") | H8: =IF(ISNUMBER(SEARCH($A8,INDEX(Index_CT!$D$2:$D$36,MATCH(H$3,Index_CT!$A$2:$A$36,0)))),"X","") | I8: =IF(ISNUMBER(SEARCH($A8,INDEX(Index_CT!$D$2:$D$36,MATCH(I$3,Index_CT!$A$2:$A$36,0)))),"X","") | J8: =IF(ISNUMBER(SEARCH($A8,INDEX(Index_CT!$D$2:$D$36,MATCH(J$3,Index_CT!$A$2:$A$36,0)))),"X","") | K8: =IF(ISNUMBER(SEARCH($A8,INDEX(Index_CT!$D$2:$D$36,MATCH(K$3,Index_CT!$A$2:$A$36,0)))),"X","") | L8: =IF(ISNUMBER(SEARCH($A8,INDEX(Index_CT!$D$2:$D$36,MATCH(L$3,Index_CT!$A$2:$A$36,0)))),"X","") -> X | ... BR8: =IF(ISNUMBER(SEARCH($A8,INDEX(Index_CT!$D$2:$D$36,MATCH(BR$3,Index_CT!$A$2:$A$36,0)))),"X","")
A9: REQ-006 | B9: Pages protégées soumises à une session | C9: Haute | D9: =COUNTIF(E9:BR9,"X") -> 2 | E9: =IF(ISNUMBER(SEARCH($A9,INDEX(Index_CT!$D$2:$D$36,MATCH(E$3,Index_CT!$A$2:$A$36,0)))),"X","") | F9: =IF(ISNUMBER(SEARCH($A9,INDEX(Index_CT!$D$2:$D$36,MATCH(F$3,Index_CT!$A$2:$A$36,0)))),"X","") | G9: =IF(ISNUMBER(SEARCH($A9,INDEX(Index_CT!$D$2:$D$36,MATCH(G$3,Index_CT!$A$2:$A$36,0)))),"X","") | H9: =IF(ISNUMBER(SEARCH($A9,INDEX(Index_CT!$D$2:$D$36,MATCH(H$3,Index_CT!$A$2:$A$36,0)))),"X","") | I9: =IF(ISNUMBER(SEARCH($A9,INDEX(Index_CT!$D$2:$D$36,MATCH(I$3,Index_CT!$A$2:$A$36,0)))),"X","") | J9: =IF(ISNUMBER(SEARCH($A9,INDEX(Index_CT!$D$2:$D$36,MATCH(J$3,Index_CT!$A$2:$A$36,0)))),"X","") | K9: =IF(ISNUMBER(SEARCH($A9,INDEX(Index_CT!$D$2:$D$36,MATCH(K$3,Index_CT!$A$2:$A$36,0)))),"X","") | L9: =IF(ISNUMBER(SEARCH($A9,INDEX(Index_CT!$D$2:$D$36,MATCH(L$3,Index_CT!$A$2:$A$36,0)))),"X","") | ... BR9: =IF(ISNUMBER(SEARCH($A9,INDEX(Index_CT!$D$2:$D$36,MATCH(BR$3,Index_CT!$A$2:$A$36,0)))),"X","")
A10: REQ-007 | B10: Compte désactivé sans accès | C10: Haute | D10: =COUNTIF(E10:BR10,"X") -> 2 | E10: =IF(ISNUMBER(SEARCH($A10,INDEX(Index_CT!$D$2:$D$36,MATCH(E$3,Index_CT!$A$2:$A$36,0)))),"X","") | F10: =IF(ISNUMBER(SEARCH($A10,INDEX(Index_CT!$D$2:$D$36,MATCH(F$3,Index_CT!$A$2:$A$36,0)))),"X","") | G10: =IF(ISNUMBER(SEARCH($A10,INDEX(Index_CT!$D$2:$D$36,MATCH(G$3,Index_CT!$A$2:$A$36,0)))),"X","") | H10: =IF(ISNUMBER(SEARCH($A10,INDEX(Index_CT!$D$2:$D$36,MATCH(H$3,Index_CT!$A$2:$A$36,0)))),"X","") | I10: =IF(ISNUMBER(SEARCH($A10,INDEX(Index_CT!$D$2:$D$36,MATCH(I$3,Index_CT!$A$2:$A$36,0)))),"X","") | J10: =IF(ISNUMBER(SEARCH($A10,INDEX(Index_CT!$D$2:$D$36,MATCH(J$3,Index_CT!$A$2:$A$36,0)))),"X","") | K10: =IF(ISNUMBER(SEARCH($A10,INDEX(Index_CT!$D$2:$D$36,MATCH(K$3,Index_CT!$A$2:$A$36,0)))),"X","") | L10: =IF(ISNUMBER(SEARCH($A10,INDEX(Index_CT!$D$2:$D$36,MATCH(L$3,Index_CT!$A$2:$A$36,0)))),"X","") | ... BR10: =IF(ISNUMBER(SEARCH($A10,INDEX(Index_CT!$D$2:$D$36,MATCH(BR$3,Index_CT!$A$2:$A$36,0)))),"X","")
A11: REQ-008 | B11: Accès au mot de passe oublié | C11: Basse | D11: =COUNTIF(E11:BR11,"X") -> 1 | E11: =IF(ISNUMBER(SEARCH($A11,INDEX(Index_CT!$D$2:$D$36,MATCH(E$3,Index_CT!$A$2:$A$36,0)))),"X","") | F11: =IF(ISNUMBER(SEARCH($A11,INDEX(Index_CT!$D$2:$D$36,MATCH(F$3,Index_CT!$A$2:$A$36,0)))),"X","") | G11: =IF(ISNUMBER(SEARCH($A11,INDEX(Index_CT!$D$2:$D$36,MATCH(G$3,Index_CT!$A$2:$A$36,0)))),"X","") | H11: =IF(ISNUMBER(SEARCH($A11,INDEX(Index_CT!$D$2:$D$36,MATCH(H$3,Index_CT!$A$2:$A$36,0)))),"X","") | I11: =IF(ISNUMBER(SEARCH($A11,INDEX(Index_CT!$D$2:$D$36,MATCH(I$3,Index_CT!$A$2:$A$36,0)))),"X","") | J11: =IF(ISNUMBER(SEARCH($A11,INDEX(Index_CT!$D$2:$D$36,MATCH(J$3,Index_CT!$A$2:$A$36,0)))),"X","") | K11: =IF(ISNUMBER(SEARCH($A11,INDEX(Index_CT!$D$2:$D$36,MATCH(K$3,Index_CT!$A$2:$A$36,0)))),"X","") | L11: =IF(ISNUMBER(SEARCH($A11,INDEX(Index_CT!$D$2:$D$36,MATCH(L$3,Index_CT!$A$2:$A$36,0)))),"X","") | ... BR11: =IF(ISNUMBER(SEARCH($A11,INDEX(Index_CT!$D$2:$D$36,MATCH(BR$3,Index_CT!$A$2:$A$36,0)))),"X","")
A12: REQ-009 | B12: Widgets du Dashboard | C12: Basse | D12: =COUNTIF(E12:BR12,"X") -> 1 | E12: =IF(ISNUMBER(SEARCH($A12,INDEX(Index_CT!$D$2:$D$36,MATCH(E$3,Index_CT!$A$2:$A$36,0)))),"X","") | F12: =IF(ISNUMBER(SEARCH($A12,INDEX(Index_CT!$D$2:$D$36,MATCH(F$3,Index_CT!$A$2:$A$36,0)))),"X","") | G12: =IF(ISNUMBER(SEARCH($A12,INDEX(Index_CT!$D$2:$D$36,MATCH(G$3,Index_CT!$A$2:$A$36,0)))),"X","") | H12: =IF(ISNUMBER(SEARCH($A12,INDEX(Index_CT!$D$2:$D$36,MATCH(H$3,Index_CT!$A$2:$A$36,0)))),"X","") | I12: =IF(ISNUMBER(SEARCH($A12,INDEX(Index_CT!$D$2:$D$36,MATCH(I$3,Index_CT!$A$2:$A$36,0)))),"X","") | J12: =IF(ISNUMBER(SEARCH($A12,INDEX(Index_CT!$D$2:$D$36,MATCH(J$3,Index_CT!$A$2:$A$36,0)))),"X","") | K12: =IF(ISNUMBER(SEARCH($A12,INDEX(Index_CT!$D$2:$D$36,MATCH(K$3,Index_CT!$A$2:$A$36,0)))),"X","") | L12: =IF(ISNUMBER(SEARCH($A12,INDEX(Index_CT!$D$2:$D$36,MATCH(L$3,Index_CT!$A$2:$A$36,0)))),"X","") | ... BR12: =IF(ISNUMBER(SEARCH($A12,INDEX(Index_CT!$D$2:$D$36,MATCH(BR$3,Index_CT!$A$2:$A$36,0)))),"X","")
A13: REQ-010 | B13: Ajout d'un utilisateur système | C13: Haute | D13: =COUNTIF(E13:BR13,"X") -> 2 | E13: =IF(ISNUMBER(SEARCH($A13,INDEX(Index_CT!$D$2:$D$36,MATCH(E$3,Index_CT!$A$2:$A$36,0)))),"X","") | F13: =IF(ISNUMBER(SEARCH($A13,INDEX(Index_CT!$D$2:$D$36,MATCH(F$3,Index_CT!$A$2:$A$36,0)))),"X","") | G13: =IF(ISNUMBER(SEARCH($A13,INDEX(Index_CT!$D$2:$D$36,MATCH(G$3,Index_CT!$A$2:$A$36,0)))),"X","") | H13: =IF(ISNUMBER(SEARCH($A13,INDEX(Index_CT!$D$2:$D$36,MATCH(H$3,Index_CT!$A$2:$A$36,0)))),"X","") | I13: =IF(ISNUMBER(SEARCH($A13,INDEX(Index_CT!$D$2:$D$36,MATCH(I$3,Index_CT!$A$2:$A$36,0)))),"X","") | J13: =IF(ISNUMBER(SEARCH($A13,INDEX(Index_CT!$D$2:$D$36,MATCH(J$3,Index_CT!$A$2:$A$36,0)))),"X","") | K13: =IF(ISNUMBER(SEARCH($A13,INDEX(Index_CT!$D$2:$D$36,MATCH(K$3,Index_CT!$A$2:$A$36,0)))),"X","") | L13: =IF(ISNUMBER(SEARCH($A13,INDEX(Index_CT!$D$2:$D$36,MATCH(L$3,Index_CT!$A$2:$A$36,0)))),"X","") | ... BR13: =IF(ISNUMBER(SEARCH($A13,INDEX(Index_CT!$D$2:$D$36,MATCH(BR$3,Index_CT!$A$2:$A$36,0)))),"X","")
A14: REQ-011 | B14: Longueur du nom d'utilisateur | C14: Haute | D14: =COUNTIF(E14:BR14,"X") -> 4 | E14: =IF(ISNUMBER(SEARCH($A14,INDEX(Index_CT!$D$2:$D$36,MATCH(E$3,Index_CT!$A$2:$A$36,0)))),"X","") | F14: =IF(ISNUMBER(SEARCH($A14,INDEX(Index_CT!$D$2:$D$36,MATCH(F$3,Index_CT!$A$2:$A$36,0)))),"X","") | G14: =IF(ISNUMBER(SEARCH($A14,INDEX(Index_CT!$D$2:$D$36,MATCH(G$3,Index_CT!$A$2:$A$36,0)))),"X","") | H14: =IF(ISNUMBER(SEARCH($A14,INDEX(Index_CT!$D$2:$D$36,MATCH(H$3,Index_CT!$A$2:$A$36,0)))),"X","") | I14: =IF(ISNUMBER(SEARCH($A14,INDEX(Index_CT!$D$2:$D$36,MATCH(I$3,Index_CT!$A$2:$A$36,0)))),"X","") | J14: =IF(ISNUMBER(SEARCH($A14,INDEX(Index_CT!$D$2:$D$36,MATCH(J$3,Index_CT!$A$2:$A$36,0)))),"X","") | K14: =IF(ISNUMBER(SEARCH($A14,INDEX(Index_CT!$D$2:$D$36,MATCH(K$3,Index_CT!$A$2:$A$36,0)))),"X","") | L14: =IF(ISNUMBER(SEARCH($A14,INDEX(Index_CT!$D$2:$D$36,MATCH(L$3,Index_CT!$A$2:$A$36,0)))),"X","") | ... BR14: =IF(ISNUMBER(SEARCH($A14,INDEX(Index_CT!$D$2:$D$36,MATCH(BR$3,Index_CT!$A$2:$A$36,0)))),"X","")
A15: REQ-012 | B15: Unicité du nom d'utilisateur | C15: Haute | D15: =COUNTIF(E15:BR15,"X") -> 1 | E15: =IF(ISNUMBER(SEARCH($A15,INDEX(Index_CT!$D$2:$D$36,MATCH(E$3,Index_CT!$A$2:$A$36,0)))),"X","") | F15: =IF(ISNUMBER(SEARCH($A15,INDEX(Index_CT!$D$2:$D$36,MATCH(F$3,Index_CT!$A$2:$A$36,0)))),"X","") | G15: =IF(ISNUMBER(SEARCH($A15,INDEX(Index_CT!$D$2:$D$36,MATCH(G$3,Index_CT!$A$2:$A$36,0)))),"X","") | H15: =IF(ISNUMBER(SEARCH($A15,INDEX(Index_CT!$D$2:$D$36,MATCH(H$3,Index_CT!$A$2:$A$36,0)))),"X","") | I15: =IF(ISNUMBER(SEARCH($A15,INDEX(Index_CT!$D$2:$D$36,MATCH(I$3,Index_CT!$A$2:$A$36,0)))),"X","") | J15: =IF(ISNUMBER(SEARCH($A15,INDEX(Index_CT!$D$2:$D$36,MATCH(J$3,Index_CT!$A$2:$A$36,0)))),"X","") | K15: =IF(ISNUMBER(SEARCH($A15,INDEX(Index_CT!$D$2:$D$36,MATCH(K$3,Index_CT!$A$2:$A$36,0)))),"X","") | L15: =IF(ISNUMBER(SEARCH($A15,INDEX(Index_CT!$D$2:$D$36,MATCH(L$3,Index_CT!$A$2:$A$36,0)))),"X","") | ... BR15: =IF(ISNUMBER(SEARCH($A15,INDEX(Index_CT!$D$2:$D$36,MATCH(BR$3,Index_CT!$A$2:$A$36,0)))),"X","")
... A38: REQ-035 | B38: Mise à jour de ses informations personnelles | C38: Moyenne | D38: =COUNTIF(E38:BR38,"X") -> 0 | E38: =IF(ISNUMBER(SEARCH($A38,INDEX(Index_CT!$D$2:$D$36,MATCH(E$3,Index_CT!$A$2:$A$36,0)))),"X","") | F38: =IF(ISNUMBER(SEARCH($A38,INDEX(Index_CT!$D$2:$D$36,MATCH(F$3,Index_CT!$A$2:$A$36,0)))),"X","") | G38: =IF(ISNUMBER(SEARCH($A38,INDEX(Index_CT!$D$2:$D$36,MATCH(G$3,Index_CT!$A$2:$A$36,0)))),"X","") | H38: =IF(ISNUMBER(SEARCH($A38,INDEX(Index_CT!$D$2:$D$36,MATCH(H$3,Index_CT!$A$2:$A$36,0)))),"X","") | I38: =IF(ISNUMBER(SEARCH($A38,INDEX(Index_CT!$D$2:$D$36,MATCH(I$3,Index_CT!$A$2:$A$36,0)))),"X","") | J38: =IF(ISNUMBER(SEARCH($A38,INDEX(Index_CT!$D$2:$D$36,MATCH(J$3,Index_CT!$A$2:$A$36,0)))),"X","") | K38: =IF(ISNUMBER(SEARCH($A38,INDEX(Index_CT!$D$2:$D$36,MATCH(K$3,Index_CT!$A$2:$A$36,0)))),"X","") | L38: =IF(ISNUMBER(SEARCH($A38,INDEX(Index_CT!$D$2:$D$36,MATCH(L$3,Index_CT!$A$2:$A$36,0)))),"X","") | ... BR38: =IF(ISNUMBER(SEARCH($A38,INDEX(Index_CT!$D$2:$D$36,MATCH(BR$3,Index_CT!$A$2:$A$36,0)))),"X","")
A39: Nb REQ (ascendante) | E39: =COUNTIF(E4:E38,"X") -> 2 | F39: =COUNTIF(F4:F38,"X") -> 1 | G39: =COUNTIF(G4:G38,"X") -> 1 | H39: =COUNTIF(H4:H38,"X") -> 1 | I39: =COUNTIF(I4:I38,"X") -> 1 | J39: =COUNTIF(J4:J38,"X") -> 1 | K39: =COUNTIF(K4:K38,"X") -> 1 | L39: =COUNTIF(L4:L38,"X") -> 1 | ... BR39: =COUNTIF(BR4:BR38,"X") -> 0

Sheet Couverture
A2: Répartition
A3: Cas de test par priorité
A4: Haute | B4: =COUNTIF(Index_CT!F2:F36,A4) -> 24
A5: Moyenne | B5: =COUNTIF(Index_CT!F2:F36,A5) -> 8
A6: Basse | B6: =COUNTIF(Index_CT!F2:F36,A6) -> 3
A7: Total | B7: =SUM(B4:B6) -> 35
A9: Cas de test par technique
A10: Partitionnement en classes d'équivalence | B10: =COUNTIF(Index_CT!G2:G36,A10) -> 13
A11: Analyse des valeurs limites | B11: =COUNTIF(Index_CT!G2:G36,A11) -> 6
A12: Test par tables de décision | B12: =COUNTIF(Index_CT!G2:G36,A12) -> 7
A13: Test de transition d'états | B13: =COUNTIF(Index_CT!G2:G36,A13) -> 6
A14: Estimation d'erreurs | B14: =COUNTIF(Index_CT!G2:G36,A14) -> 2
A15: Test basé sur des checklists | B15: =COUNTIF(Index_CT!G2:G36,A15) -> 1
A16: Total | B16: =SUM(B10:B15) -> 35
A18: Cas de test par module
A19: Authentification (Login / Logout) | B19: =COUNTIF(Index_CT!E2:E36,A19) -> 13
A20: Dashboard (tableau de bord) | B20: =COUNTIF(Index_CT!E2:E36,A20) -> 1
A21: Admin - Gestion des utilisateurs (User Management) | B21: =COUNTIF(Index_CT!E2:E36,A21) -> 21
A22: PIM - Gestion des employés | B22: =COUNTIF(Index_CT!E2:E36,A22) -> 0
A23: Leave (congés) | B23: =COUNTIF(Index_CT!E2:E36,A23) -> 0
A24: My Info (informations personnelles) | B24: =COUNTIF(Index_CT!E2:E36,A24) -> 0
A25: Total | B25: =SUM(B19:B24) -> 35
A27: Couverture = couverture de conception (chaque exigence liée à au moins un cas de test conçu). Aucun test n'a été exécuté.
